<sdf version='1.6'>
  <world name='default'>
    <light name='sun' type='directional'>
      <cast_shadows>1</cast_shadows>
      <pose frame=''>0 0 10 0 -0 0</pose>
      <diffuse>0.8 0.8 0.8 1</diffuse>
      <specular>0.2 0.2 0.2 1</specular>
      <attenuation>
        <range>1000</range>
        <constant>0.9</constant>
        <linear>0.01</linear>
        <quadratic>0.001</quadratic>
      </attenuation>
      <direction>-0.5 0.1 -0.9</direction>
    </light>
    <model name='ground_plane'>
      <static>1</static>
      <link name='link'>
        <collision name='collision'>
          <geometry>
            <plane>
              <normal>0 0 1</normal>
              <size>100 100</size>
            </plane>
          </geometry>
          <surface>
            <contact>
              <collide_bitmask>65535</collide_bitmask>
              <ode/>
            </contact>
            <friction>
              <ode>
                <mu>100</mu>
                <mu2>50</mu2>
              </ode>
              <torsional>
                <ode/>
              </torsional>
            </friction>
            <bounce/>
          </surface>
          <max_contacts>10</max_contacts>
        </collision>
        <visual name='visual'>
          <cast_shadows>0</cast_shadows>
          <geometry>
            <plane>
              <normal>0 0 1</normal>
              <size>100 100</size>
            </plane>
          </geometry>
          <material>
            <script>
              <uri>file://media/materials/scripts/gazebo.material</uri>
              <name>Gazebo/Grey</name>
            </script>
          </material>
        </visual>
        <self_collide>0</self_collide>
        <enable_wind>0</enable_wind>
        <kinematic>0</kinematic>
      </link>
    </model>
    <gravity>0 0 -9.8</gravity>
    <magnetic_field>6e-06 2.3e-05 -4.2e-05</magnetic_field>
    <atmosphere type='adiabatic'/>
    <physics name='default_physics' default='0' type='ode'>
      <max_step_size>0.001</max_step_size>
      <real_time_factor>1</real_time_factor>
      <real_time_update_rate>1000</real_time_update_rate>
    </physics>
    <scene>
      <ambient>0.4 0.4 0.4 1</ambient>
      <background>0.7 0.7 0.7 1</background>
      <shadows>1</shadows>
    </scene>
    <wind/>
    <spherical_coordinates>
      <surface_model>EARTH_WGS84</surface_model>
      <latitude_deg>0</latitude_deg>
      <longitude_deg>0</longitude_deg>
      <elevation>0</elevation>
      <heading_deg>0</heading_deg>
    </spherical_coordinates>
    <model name='living_lab'>
      <pose frame=''>1.99884 -0.112712 0 0 -0 0</pose>
      <link name='Wall_0'>
        <collision name='Wall_0_Collision'>
          <geometry>
            <box>
              <size>3.25 0.15 2.5</size>
            </box>
          </geometry>
          <pose frame=''>0 0 1.25 0 -0 0</pose>
          <max_contacts>10</max_contacts>
          <surface>
            <contact>
              <ode/>
            </contact>
            <bounce/>
            <friction>
              <torsional>
                <ode/>
              </torsional>
              <ode/>
            </friction>
          </surface>
        </collision>
        <visual name='Wall_0_Visual'>
          <pose frame=''>0 0 1.25 0 -0 0</pose>
          <geometry>
            <box>
              <size>3.25 0.15 2.5</size>
            </box>
          </geometry>
          <material>
            <script>
              <uri>file://media/materials/scripts/gazebo.material</uri>
              <name>Gazebo/Grey</name>
            </script>
            <ambient>1 1 1 1</ambient>
          </material>
          <meta>
            <layer>0</layer>
          </meta>
        </visual>
        <pose frame=''>-3.83237 4.17394 0 0 -0 0</pose>
        <self_collide>0</self_collide>
        <enable_wind>0</enable_wind>
        <kinematic>0</kinematic>
      </link>
      <link name='Wall_1'>
        <collision name='Wall_1_Collision'>
          <geometry>
            <box>
              <size>1.75 0.15 2.5</size>
            </box>
          </geometry>
          <pose frame=''>0 0 1.25 0 -0 0</pose>
          <max_contacts>10</max_contacts>
          <surface>
            <contact>
              <ode/>
            </contact>
            <bounce/>
            <friction>
              <torsional>
                <ode/>
              </torsional>
              <ode/>
            </friction>
          </surface>
        </collision>
        <visual name='Wall_1_Visual'>
          <pose frame=''>0 0 1.25 0 -0 0</pose>
          <geometry>
            <box>
              <size>1.75 0.15 2.5</size>
            </box>
          </geometry>
          <material>
            <script>
              <uri>file://media/materials/scripts/gazebo.material</uri>
              <name>Gazebo/Grey</name>
            </script>
            <ambient>1 1 1 1</ambient>
          </material>
          <meta>
            <layer>0</layer>
          </meta>
        </visual>
        <pose frame=''>-2.28237 3.37394 0 0 -0 -1.5708</pose>
        <self_collide>0</self_collide>
        <enable_wind>0</enable_wind>
        <kinematic>0</kinematic>
      </link>
      <link name='Wall_10'>
        <collision name='Wall_10_Collision'>
          <geometry>
            <box>
              <size>7 0.15 2.5</size>
            </box>
          </geometry>
          <pose frame=''>0 0 1.25 0 -0 0</pose>
          <max_contacts>10</max_contacts>
          <surface>
            <contact>
              <ode/>
            </contact>
            <bounce/>
            <friction>
              <torsional>
                <ode/>
              </torsional>
              <ode/>
            </friction>
          </surface>
        </collision>
        <visual name='Wall_10_Visual'>
          <pose frame=''>0 0 1.25 0 -0 0</pose>
          <geometry>
            <box>
              <size>7 0.15 2.5</size>
            </box>
          </geometry>
          <material>
            <script>
              <uri>file://media/materials/scripts/gazebo.material</uri>
              <name>Gazebo/Grey</name>
            </script>
            <ambient>1 1 1 1</ambient>
          </material>
          <meta>
            <layer>0</layer>
          </meta>
        </visual>
        <pose frame=''>1.99263 4.17394 0 0 -0 0</pose>
        <self_collide>0</self_collide>
        <enable_wind>0</enable_wind>
        <kinematic>0</kinematic>
      </link>
      <link name='Wall_12'>
        <collision name='Wall_12_Collision'>
          <geometry>
            <box>
              <size>8.5 0.15 2.5</size>
            </box>
          </geometry>
          <pose frame=''>0 0 1.25 0 -0 0</pose>
          <max_contacts>10</max_contacts>
          <surface>
            <contact>
              <ode/>
            </contact>
            <bounce/>
            <friction>
              <torsional>
                <ode/>
              </torsional>
              <ode/>
            </friction>
          </surface>
        </collision>
        <visual name='Wall_12_Visual'>
          <pose frame=''>0 0 1.25 0 -0 0</pose>
          <geometry>
            <box>
              <size>8.5 0.15 2.5</size>
            </box>
          </geometry>
          <material>
            <script>
              <uri>file://media/materials/scripts/gazebo.material</uri>
              <name>Gazebo/Grey</name>
            </script>
            <ambient>1 1 1 1</ambient>
          </material>
          <meta>
            <layer>0</layer>
          </meta>
        </visual>
        <pose frame=''>5.41763 -0.001063 0 0 -0 -1.5708</pose>
        <self_collide>0</self_collide>
        <enable_wind>0</enable_wind>
        <kinematic>0</kinematic>
      </link>
      <link name='Wall_13'>
        <collision name='Wall_13_Collision'>
          <geometry>
            <box>
              <size>5 0.15 2.5</size>
            </box>
          </geometry>
          <pose frame=''>0 0 1.25 0 -0 0</pose>
          <max_contacts>10</max_contacts>
          <surface>
            <contact>
              <ode/>
            </contact>
            <bounce/>
            <friction>
              <torsional>
                <ode/>
              </torsional>
              <ode/>
            </friction>
          </surface>
        </collision>
        <visual name='Wall_13_Visual'>
          <pose frame=''>0 0 1.25 0 -0 0</pose>
          <geometry>
            <box>
              <size>5 0.15 2.5</size>
            </box>
          </geometry>
          <material>
            <script>
              <uri>file://media/materials/scripts/gazebo.material</uri>
              <name>Gazebo/Grey</name>
            </script>
            <ambient>1 1 1 1</ambient>
          </material>
          <meta>
            <layer>0</layer>
          </meta>
        </visual>
        <pose frame=''>2.99263 -4.17606 0 0 -0 3.14159</pose>
        <self_collide>0</self_collide>
        <enable_wind>0</enable_wind>
        <kinematic>0</kinematic>
      </link>
      <link name='Wall_15'>
        <collision name='Wall_15_Collision'>
          <geometry>
            <box>
              <size>4.75 0.15 2.5</size>
            </box>
          </geometry>
          <pose frame=''>0 0 1.25 0 -0 0</pose>
          <max_contacts>10</max_contacts>
          <surface>
            <contact>
              <ode/>
            </contact>
            <bounce/>
            <friction>
              <torsional>
                <ode/>
              </torsional>
              <ode/>
            </friction>
          </surface>
        </collision>
        <visual name='Wall_15_Visual'>
          <pose frame=''>0 0 1.25 0 -0 0</pose>
          <geometry>
            <box>
              <size>4.75 0.15 2.5</size>
            </box>
          </geometry>
          <material>
            <script>
              <uri>file://media/materials/scripts/gazebo.material</uri>
              <name>Gazebo/Grey</name>
            </script>
            <ambient>1 1 1 1</ambient>
          </material>
          <meta>
            <layer>0</layer>
          </meta>
        </visual>
        <pose frame=''>-3.12746 -4.16076 0 0 -0 3.14159</pose>
        <self_collide>0</self_collide>
        <enable_wind>0</enable_wind>
        <kinematic>0</kinematic>
      </link>
      <link name='Wall_17'>
        <collision name='Wall_17_Collision'>
          <geometry>
            <box>
              <size>8.48482 0.15 2.5</size>
            </box>
          </geometry>
          <pose frame=''>0 0 1.25 0 -0 0</pose>
          <max_contacts>10</max_contacts>
          <surface>
            <contact>
              <ode/>
            </contact>
            <bounce/>
            <friction>
              <torsional>
                <ode/>
              </torsional>
              <ode/>
            </friction>
          </surface>
        </collision>
        <visual name='Wall_17_Visual'>
          <pose frame=''>0 0 1.25 0 -0 0</pose>
          <geometry>
            <box>
              <size>8.48482 0.15 2.5</size>
            </box>
          </geometry>
          <material>
            <script>
              <uri>file://media/materials/scripts/gazebo.material</uri>
              <name>Gazebo/Grey</name>
            </script>
            <ambient>1 1 1 1</ambient>
          </material>
          <meta>
            <layer>0</layer>
          </meta>
        </visual>
        <pose frame=''>-5.40491 0.006586 0 0 -0 1.56539</pose>
        <self_collide>0</self_collide>
        <enable_wind>0</enable_wind>
        <kinematic>0</kinematic>
      </link>
      <link name='Wall_19'>
        <collision name='Wall_19_Collision'>
          <geometry>
            <box>
              <size>3.25 0.15 2.5</size>
            </box>
          </geometry>
          <pose frame=''>0 0 1.25 0 -0 0</pose>
          <max_contacts>10</max_contacts>
          <surface>
            <contact>
              <ode/>
            </contact>
            <bounce/>
            <friction>
              <torsional>
                <ode/>
              </torsional>
              <ode/>
            </friction>
          </surface>
        </collision>
        <visual name='Wall_19_Visual'>
          <pose frame=''>0 0 1.25 0 -0 0</pose>
          <geometry>
            <box>
              <size>3.25 0.15 2.5</size>
            </box>
          </geometry>
          <material>
            <script>
              <uri>file://media/materials/scripts/gazebo.material</uri>
              <name>Gazebo/Grey</name>
            </script>
            <ambient>1 1 1 1</ambient>
          </material>
          <meta>
            <layer>0</layer>
          </meta>
        </visual>
        <pose frame=''>-3.82313 -0.037483 0 0 -0 0</pose>
        <self_collide>0</self_collide>
        <enable_wind>0</enable_wind>
        <kinematic>0</kinematic>
      </link>
      <link name='Wall_2'>
        <collision name='Wall_2_Collision'>
          <geometry>
            <box>
              <size>1 0.15 2.5</size>
            </box>
          </geometry>
          <pose frame=''>0 0 1.25 0 -0 0</pose>
          <max_contacts>10</max_contacts>
          <surface>
            <contact>
              <ode/>
            </contact>
            <bounce/>
            <friction>
              <torsional>
                <ode/>
              </torsional>
              <ode/>
            </friction>
          </surface>
        </collision>
        <visual name='Wall_2_Visual'>
          <pose frame=''>0 0 1.25 0 -0 0</pose>
          <geometry>
            <box>
              <size>1 0.15 2.5</size>
            </box>
          </geometry>
          <material>
            <script>
              <uri>file://media/materials/scripts/gazebo.material</uri>
              <name>Gazebo/Grey</name>
            </script>
            <ambient>1 1 1 1</ambient>
          </material>
          <meta>
            <layer>0</layer>
          </meta>
        </visual>
        <pose frame=''>-1.85737 2.57394 0 0 -0 0</pose>
        <self_collide>0</self_collide>
        <enable_wind>0</enable_wind>
        <kinematic>0</kinematic>
      </link>
      <link name='Wall_21'>
        <collision name='Wall_21_Collision'>
          <geometry>
            <box>
              <size>3.25 0.15 2.5</size>
            </box>
          </geometry>
          <pose frame=''>0 0 1.25 0 -0 0</pose>
          <max_contacts>10</max_contacts>
          <surface>
            <contact>
              <ode/>
            </contact>
            <bounce/>
            <friction>
              <torsional>
                <ode/>
              </torsional>
              <ode/>
            </friction>
          </surface>
        </collision>
        <visual name='Wall_21_Visual'>
          <pose frame=''>0 0 1.25 0 -0 0</pose>
          <geometry>
            <box>
              <size>3.25 0.15 2.5</size>
            </box>
          </geometry>
          <material>
            <script>
              <uri>file://media/materials/scripts/gazebo.material</uri>
              <name>Gazebo/Grey</name>
            </script>
            <ambient>1 1 1 1</ambient>
          </material>
          <meta>
            <layer>0</layer>
          </meta>
        </visual>
        <pose frame=''>3.87786 0.586038 0 0 -0 3.14159</pose>
        <self_collide>0</self_collide>
        <enable_wind>0</enable_wind>
        <kinematic>0</kinematic>
      </link>
      <link name='Wall_24'>
        <collision name='Wall_24_Collision'>
          <geometry>
            <box>
              <size>1.5 0.15 2.5</size>
            </box>
          </geometry>
          <pose frame=''>0 0 1.25 0 -0 0</pose>
          <max_contacts>10</max_contacts>
          <surface>
            <contact>
              <ode/>
            </contact>
            <bounce/>
            <friction>
              <torsional>
                <ode/>
              </torsional>
              <ode/>
            </friction>
          </surface>
        </collision>
        <visual name='Wall_24_Visual'>
          <pose frame=''>0 0 1.25 0 -0 0</pose>
          <geometry>
            <box>
              <size>1.5 0.15 2.5</size>
            </box>
          </geometry>
          <material>
            <script>
              <uri>file://media/materials/scripts/gazebo.material</uri>
              <name>Gazebo/Grey</name>
            </script>
            <ambient>1 1 1 1</ambient>
          </material>
          <meta>
            <layer>0</layer>
          </meta>
        </visual>
        <pose frame=''>0.319016 3.50106 0 0 -0 -1.5708</pose>
        <self_collide>0</self_collide>
        <enable_wind>0</enable_wind>
        <kinematic>0</kinematic>
      </link>
      <link name='Wall_3'>
        <collision name='Wall_3_Collision'>
          <geometry>
            <box>
              <size>1.25 0.15 2.5</size>
            </box>
          </geometry>
          <pose frame=''>0 0 1.25 0 -0 0</pose>
          <max_contacts>10</max_contacts>
          <surface>
            <contact>
              <ode/>
            </contact>
            <bounce/>
            <friction>
              <torsional>
                <ode/>
              </torsional>
              <ode/>
            </friction>
          </surface>
        </collision>
        <visual name='Wall_3_Visual'>
          <pose frame=''>0 0 1.25 0 -0 0</pose>
          <geometry>
            <box>
              <size>1.25 0.15 2.5</size>
            </box>
          </geometry>
          <material>
            <script>
              <uri>file://media/materials/scripts/gazebo.material</uri>
              <name>Gazebo/Grey</name>
            </script>
            <ambient>1 1 1 1</ambient>
          </material>
          <meta>
            <layer>0</layer>
          </meta>
        </visual>
        <pose frame=''>-1.43237 2.02394 0 0 -0 -1.5708</pose>
        <self_collide>0</self_collide>
        <enable_wind>0</enable_wind>
        <kinematic>0</kinematic>
      </link>
      <link name='Wall_4'>
        <collision name='Wall_4_Collision'>
          <geometry>
            <box>
              <size>1.89133 0.15 2.5</size>
            </box>
          </geometry>
          <pose frame=''>0 0 1.25 0 -0 0</pose>
          <max_contacts>10</max_contacts>
          <surface>
            <contact>
              <ode/>
            </contact>
            <bounce/>
            <friction>
              <torsional>
                <ode/>
              </torsional>
              <ode/>
            </friction>
          </surface>
        </collision>
        <visual name='Wall_4_Visual'>
          <pose frame=''>0 0 1.25 0 -0 0</pose>
          <geometry>
            <box>
              <size>1.89133 0.15 2.5</size>
            </box>
          </geometry>
          <material>
            <script>
              <uri>file://media/materials/scripts/gazebo.material</uri>
              <name>Gazebo/Grey</name>
            </script>
            <ambient>1 1 1 1</ambient>
          </material>
          <meta>
            <layer>0</layer>
          </meta>
        </visual>
        <pose frame=''>-0.561748 1.47291 0 0 -0 -0.001179</pose>
        <self_collide>0</self_collide>
        <enable_wind>0</enable_wind>
        <kinematic>0</kinematic>
      </link>
      <link name='Wall_9'>
        <collision name='Wall_9_Collision'>
          <geometry>
            <box>
              <size>1.75 0.15 2.5</size>
            </box>
          </geometry>
          <pose frame=''>0 0 1.25 0 -0 0</pose>
          <max_contacts>10</max_contacts>
          <surface>
            <contact>
              <ode/>
            </contact>
            <bounce/>
            <friction>
              <torsional>
                <ode/>
              </torsional>
              <ode/>
            </friction>
          </surface>
        </collision>
        <visual name='Wall_9_Visual'>
          <pose frame=''>0 0 1.25 0 -0 0</pose>
          <geometry>
            <box>
              <size>1.75 0.15 2.5</size>
            </box>
          </geometry>
          <material>
            <script>
              <uri>file://media/materials/scripts/gazebo.material</uri>
              <name>Gazebo/Grey</name>
            </script>
            <ambient>1 1 1 1</ambient>
          </material>
          <meta>
            <layer>0</layer>
          </meta>
        </visual>
        <pose frame=''>-1.43237 3.37394 0 0 -0 1.5708</pose>
        <self_collide>0</self_collide>
        <enable_wind>0</enable_wind>
        <kinematic>0</kinematic>
      </link>
      <static>1</static>
    </model>
    <state world_name='default'>
      <sim_time>1548 883000000</sim_time>
      <real_time>1522 224869528</real_time>
      <wall_time>1604991966 905277786</wall_time>
      <iterations>1483205</iterations>
      <model name='cafe_table'>
        <pose frame=''>-2.23542 -1.97252 0 0 -0 0</pose>
        <scale>1 1 1</scale>
        <link name='link'>
          <pose frame=''>-2.23542 -1.97252 0 0 -0 0</pose>
          <velocity>0 0 0 0 -0 0</velocity>
          <acceleration>0 0 0 0 -0 0</acceleration>
          <wrench>0 0 0 0 -0 0</wrench>
        </link>
      </model>
      <model name='coke_can'>
        <pose frame=''>2.20004 -2.69993 1.01185 0.018143 -0.009916 -0.003368</pose>
        <scale>1 1 1</scale>
        <link name='link'>
          <pose frame=''>2.20004 -2.69993 1.01185 0.018143 -0.009916 -0.003368</pose>
          <velocity>0 0 0 0 -0 0</velocity>
          <acceleration>-9e-06 -0.000147 -1.8e-05 0.002602 -0.000161 -0.000131</acceleration>
          <wrench>-3e-06 -5.7e-05 -7e-06 0 -0 0</wrench>
        </link>
      </model>
      <model name='ground_plane'>
        <pose frame=''>0 0 0 0 -0 0</pose>
        <scale>1 1 1</scale>
        <link name='link'>
          <pose frame=''>0 0 0 0 -0 0</pose>
          <velocity>0 0 0 0 -0 0</velocity>
          <acceleration>0 0 0 0 -0 0</acceleration>
          <wrench>0 0 0 0 -0 0</wrench>
        </link>
      </model>
      <model name='living_lab'>
        <pose frame=''>0 0 0 0 -0 0</pose>
        <scale>1 1 1</scale>
        <link name='Wall_0'>
          <pose frame=''>-3.83237 4.17394 0 0 -0 0</pose>
          <velocity>0 0 0 0 -0 0</velocity>
          <acceleration>0 0 0 0 -0 0</acceleration>
          <wrench>0 0 0 0 -0 0</wrench>
        </link>
        <link name='Wall_1'>
          <pose frame=''>-2.28237 3.37394 0 0 0 -1.5708</pose>
          <velocity>0 0 0 0 -0 0</velocity>
          <acceleration>0 0 0 0 -0 0</acceleration>
          <wrench>0 0 0 0 -0 0</wrench>
        </link>
        <link name='Wall_10'>
          <pose frame=''>1.99263 4.17394 0 0 -0 0</pose>
          <velocity>0 0 0 0 -0 0</velocity>
          <acceleration>0 0 0 0 -0 0</acceleration>
          <wrench>0 0 0 0 -0 0</wrench>
        </link>
        <link name='Wall_12'>
          <pose frame=''>5.41763 -0.001063 0 0 0 -1.5708</pose>
          <velocity>0 0 0 0 -0 0</velocity>
          <acceleration>0 0 0 0 -0 0</acceleration>
          <wrench>0 0 0 0 -0 0</wrench>
        </link>
        <link name='Wall_13'>
          <pose frame=''>2.99263 -4.17606 0 0 -0 3.14159</pose>
          <velocity>0 0 0 0 -0 0</velocity>
          <acceleration>0 0 0 0 -0 0</acceleration>
          <wrench>0 0 0 0 -0 0</wrench>
        </link>
        <link name='Wall_15'>
          <pose frame=''>-3.12746 -4.16076 0 0 -0 3.14159</pose>
          <velocity>0 0 0 0 -0 0</velocity>
          <acceleration>0 0 0 0 -0 0</acceleration>
          <wrench>0 0 0 0 -0 0</wrench>
        </link>
        <link name='Wall_17'>
          <pose frame=''>-5.40491 0.006586 0 0 -0 1.56539</pose>
          <velocity>0 0 0 0 -0 0</velocity>
          <acceleration>0 0 0 0 -0 0</acceleration>
          <wrench>0 0 0 0 -0 0</wrench>
        </link>
        <link name='Wall_19'>
          <pose frame=''>-3.82313 -0.037483 0 0 -0 0</pose>
          <velocity>0 0 0 0 -0 0</velocity>
          <acceleration>0 0 0 0 -0 0</acceleration>
          <wrench>0 0 0 0 -0 0</wrench>
        </link>
        <link name='Wall_2'>
          <pose frame=''>-1.85737 2.57394 0 0 -0 0</pose>
          <velocity>0 0 0 0 -0 0</velocity>
          <acceleration>0 0 0 0 -0 0</acceleration>
          <wrench>0 0 0 0 -0 0</wrench>
        </link>
        <link name='Wall_21'>
          <pose frame=''>3.87786 0.586038 0 0 -0 3.14159</pose>
          <velocity>0 0 0 0 -0 0</velocity>
          <acceleration>0 0 0 0 -0 0</acceleration>
          <wrench>0 0 0 0 -0 0</wrench>
        </link>
        <link name='Wall_24'>
          <pose frame=''>0.319016 3.50106 0 0 0 -1.5708</pose>
          <velocity>0 0 0 0 -0 0</velocity>
          <acceleration>0 0 0 0 -0 0</acceleration>
          <wrench>0 0 0 0 -0 0</wrench>
        </link>
        <link name='Wall_3'>
          <pose frame=''>-1.43237 2.02394 0 0 0 -1.5708</pose>
          <velocity>0 0 0 0 -0 0</velocity>
          <acceleration>0 0 0 0 -0 0</acceleration>
          <wrench>0 0 0 0 -0 0</wrench>
        </link>
        <link name='Wall_4'>
          <pose frame=''>-0.561748 1.47291 0 0 0 -0.001179</pose>
          <velocity>0 0 0 0 -0 0</velocity>
          <acceleration>0 0 0 0 -0 0</acceleration>
          <wrench>0 0 0 0 -0 0</wrench>
        </link>
        <link name='Wall_9'>
          <pose frame=''>-1.43237 3.37394 0 0 -0 1.5708</pose>
          <velocity>0 0 0 0 -0 0</velocity>
          <acceleration>0 0 0 0 -0 0</acceleration>
          <wrench>0 0 0 0 -0 0</wrench>
        </link>
      </model>
      <model name='living_lab_robot'>
        <pose frame=''>0.270077 -0.001495 0.001432 1e-06 -1.5e-05 -0.015817</pose>
        <scale>1 1 1</scale>
        <link name='arm_base'>
          <pose frame=''>0.255046 -0.001258 0.94911 2e-06 0.000229 -0.015818</pose>
          <velocity>0.00046 -1.4e-05 -0.000437 0.000142 0.001538 -1e-06</velocity>
          <acceleration>0.407249 -0.008847 -0.557954 0.769587 1.33035 -0.003254</acceleration>
          <wrench>0.02035 -0.000442 -0.027881 0 -0 0</wrench>
        </link>
        <link name='arm_link1'>
          <pose frame=''>0.411136 -0.003727 0.897859 1.9e-05 0.000209 -0.015818</pose>
          <velocity>0.000443 -8e-06 -0.000565 0.0002 0.005632 -5e-06</velocity>
          <acceleration>0.442847 -0.007788 -0.751227 0.261911 -0.645212 -0.005353</acceleration>
          <wrench>0.022439 -0.000395 -0.038065 0 -0 0</wrench>
        </link>
        <link name='arm_link2'>
          <pose frame=''>0.444132 -0.004249 0.897852 1.9e-05 0.000209 -0.015818</pose>
          <velocity>0.00044 -8e-06 -0.000803 0.000202 0.005589 -5e-06</velocity>
          <acceleration>0.485796 -0.010366 -1.72166 -0.015726 -0.692626 -0.005214</acceleration>
          <wrench>0.043722 -0.000933 -0.154949 0 -0 0</wrench>
        </link>
        <link name='arm_link3'>
          <pose frame=''>0.708105 -0.008426 0.927797 1.9e-05 0.000209 -0.015818</pose>
          <velocity>0.000599 -1.5e-05 -0.002326 0.000201 0.005282 -8e-06</velocity>
          <acceleration>0.382544 -0.007514 -2.92712 0.066755 -1.00135 -0.007909</acceleration>
          <wrench>0.030603 -0.000601 -0.234169 0 -0 0</wrench>
        </link>
        <link name='arm_link4'>
          <pose frame=''>0.939069 -0.012079 0.88575 3.7e-05 0.000185 -0.015818</pose>
          <velocity>0.000412 -9e-06 -0.003733 0.000254 0.008688 -1.5e-05</velocity>
          <acceleration>0.412401 -0.009888 -3.96688 -2.79345 0.729179 3.12711</acceleration>
          <wrench>0.011122 -0.000267 -0.106987 0 -0 0</wrench>
        </link>
        <link name='arm_link5'>
          <pose frame=''>0.966066 -0.012506 0.885746 3.7e-05 0.000185 -0.015818</pose>
          <velocity>0.000428 -1.1e-05 -0.004147 0.000254 0.008623 -1.9e-05</velocity>
          <acceleration>0.423431 -0.012024 -4.7228 -2.88661 0.801828 3.12316</acceleration>
          <wrench>0.01645 -0.000467 -0.183481 0 -0 0</wrench>
        </link>
        <link name='arm_link6'>
          <pose frame=''>1.08905 -0.014451 0.885723 4e-05 0.000181 -0.015818</pose>
          <velocity>0.000418 -1.3e-05 -0.005124 0.000255 0.008978 -2.8e-05</velocity>
          <acceleration>0.428081 -0.013776 -5.39267 -2.84547 0.445414 3.11411</acceleration>
          <wrench>0.169007 -0.005439 -2.12903 0 -0 0</wrench>
        </link>
        <link name='base_footprint'>
          <pose frame=''>0.270077 -0.001495 0.001432 1e-06 -1.5e-05 -0.015817</pose>
          <velocity>0.000349 8e-06 0.006025 2e-05 -0.000192 1e-06</velocity>
          <acceleration>0.315267 0.004495 6.02489 0.019512 -0.191589 0.000686</acceleration>
          <wrench>17.3397 0.247231 331.369 0 -0 0</wrench>
        </link>
        <link name='body_assy'>
          <pose frame=''>0.270072 -0.001496 0.306931 1e-06 -1.6e-05 -0.015818</pose>
          <velocity>0.000148 7e-06 0.005929 2e-05 0.000227 6e-06</velocity>
          <acceleration>0.233707 -0.000399 5.92941 0.025312 0.227285 0.005581</acceleration>
          <wrench>7.0603 -0.012051 179.128 0 -0 0</wrench>
        </link>
        <link name='elevation_module'>
          <pose frame=''>0.220056 -0.000705 0.97192 2e-06 0.000236 -0.015818</pose>
          <velocity>0.000273 -1.2e-05 -0.000555 8.2e-05 0.000427 4e-06</velocity>
          <acceleration>0.273317 -0.011591 -0.555001 0.366785 0.484839 0.004847</acceleration>
          <wrench>2.8179 -0.119507 -5.72206 0 -0 0</wrench>
        </link>
        <link name='gripper_l_finger_link'>
          <pose frame=''>1.19416 -0.008111 0.885707 5.2e-05 0.000166 -0.01584</pose>
          <velocity>0.00042 -1.5e-05 -0.006414 -0.001207 0.010835 0.006839</velocity>
          <acceleration>0.376628 0.051308 -6.52642 -1.59684 -1.52917 0.556717</acceleration>
          <wrench>0.009679 0.001319 -0.167729 0 -0 0</wrench>
        </link>
        <link name='gripper_l_inner_link'>
          <pose frame=''>1.13717 -0.007211 0.885717 6.3e-05 0.000152 -0.01579</pose>
          <velocity>0.000421 -2.8e-05 -0.005783 -0.002524 0.012484 0.000177</velocity>
          <acceleration>0.421136 -0.022417 -6.15097 -2.91783 -0.049166 0.177151</acceleration>
          <wrench>0.006654 -0.000354 -0.097185 0 -0 0</wrench>
        </link>
        <link name='gripper_l_outer_link'>
          <pose frame=''>1.12674 0.003555 0.885718 -4.8e-05 0.000192 -0.420762</pose>
          <velocity>0.000419 -1.4e-05 -0.00556 0.001424 0.006988 0.004843</velocity>
          <acceleration>0.362899 0.098138 -5.70543 -0.579491 -0.727359 1.70467</acceleration>
          <wrench>0.004718 0.001276 -0.074171 0 -0 0</wrench>
        </link>
        <link name='gripper_r_finger_link'>
          <pose frame=''>1.19391 -0.024115 0.885706 3.2e-05 0.000169 -0.01583</pose>
          <velocity>0.000421 5.7e-05 -0.006381 0.001195 0.010347 -0.008162</velocity>
          <acceleration>0.367634 -0.020437 -6.48663 -2.31924 -0.742465 1.26185</acceleration>
          <wrench>0.009448 -0.000525 -0.166706 0 -0 0</wrench>
        </link>
        <link name='gripper_r_inner_link'>
          <pose frame=''>1.13692 -0.023209 0.885716 2e-05 0.000156 -0.01588</pose>
          <velocity>0.000422 -1.3e-05 -0.005776 0.002654 0.011921 0.001223</velocity>
          <acceleration>0.422797 0.023253 -6.13212 2.27472 -0.66736 1.22249</acceleration>
          <wrench>0.00668 0.000367 -0.096887 0 -0 0</wrench>
        </link>
        <link name='gripper_r_outer_link'>
          <pose frame=''>1.12615 -0.03364 0.885716 0.000122 0.000165 0.389127</pose>
          <velocity>0.000419 -1.3e-05 -0.005557 -0.000952 0.006455 -0.004571</velocity>
          <acceleration>0.362449 -0.11699 -5.69206 -1.23855 0.587145 -1.43229</acceleration>
          <wrench>0.004712 -0.001521 -0.073997 0 -0 0</wrench>
        </link>
        <link name='head_assy'>
          <pose frame=''>0.270056 -0.001496 1.28993 1e-06 -2.3e-05 -0.015824</pose>
          <velocity>-1.3e-05 -7e-06 0.005806 3.3e-05 0.001462 2e-06</velocity>
          <acceleration>-0.191721 -0.002717 5.80589 0.032594 1.46157 -9.4e-05</acceleration>
          <wrench>-3.17211 -0.044957 96.0608 0 -0 0</wrench>
        </link>
        <link name='head_screen'>
          <pose frame=''>0.371092 -0.003095 1.17795 1e-06 5e-06 -0.015824</pose>
          <velocity>-0.000287 2e-06 0.004905 0.000579 0.037165 -6e-06</velocity>
          <acceleration>-1.97764 0.028595 4.36658 0.970808 -0.522372 -0.002118</acceleration>
          <wrench>-20.1456 0.291292 44.481 0 -0 0</wrench>
        </link>
        <link name='head_tilt_unit'>
          <pose frame=''>0.368044 -0.003047 1.27392 2e-06 -1.6e-05 -0.015824</pose>
          <velocity>-0.000235 -3e-06 0.004818 0.000204 0.007435 -7e-06</velocity>
          <acceleration>0.192278 -0.013875 5.54362 0.411847 -0.393782 -3.10845</acceleration>
          <wrench>3.96325 -0.285999 114.266 0 -0 0</wrench>
        </link>
        <link name='omni_wheel_1'>
          <pose frame=''>0.41492 0.240462 0.065008 0.00063 1.43224 -0.53879</pose>
          <velocity>0.000124 -8.3e-05 0.016643 0.014257 0.001657 0.000164</velocity>
          <acceleration>0.123947 -0.083404 16.6256 -0.097734 -0.381462 0.163715</acceleration>
          <wrench>0.052058 -0.03503 6.98275 0 -0 0</wrench>
        </link>
        <link name='omni_wheel_2'>
          <pose frame=''>-0.011887 0.002964 0.065009 0.000341 1.43708 1.55532</pose>
          <velocity>0.00055 -8.5e-05 0.017135 -0.001395 0.008794 -4e-06</velocity>
          <acceleration>0.549601 -0.084845 17.122 -0.8071 1.25694 -0.003919</acceleration>
          <wrench>0.230832 -0.035635 7.19124 0 -0 0</wrench>
        </link>
        <link name='omni_wheel_3'>
          <pose frame=''>0.407195 -0.247914 0.065008 3.14145 -0.923089 0.507895</pose>
          <velocity>0.000172 6e-06 0.016631 -0.015247 0.002383 -0.00018</velocity>
          <acceleration>0.172334 0.006277 16.6133 -0.787281 0.345903 -0.1796</acceleration>
          <wrench>0.07238 0.002636 6.97757 0 -0 0</wrench>
        </link>
      </model>
      <model name='table'>
        <pose frame=''>2.10684 -2.81196 0 0 -0 0</pose>
        <scale>1 1 1</scale>
        <link name='link'>
          <pose frame=''>2.10684 -2.81196 0 0 -0 0</pose>
          <velocity>0 0 0 0 -0 0</velocity>
          <acceleration>0 0 0 0 -0 0</acceleration>
          <wrench>0 0 0 0 -0 0</wrench>
        </link>
      </model>
      <light name='sun'>
        <pose frame=''>0 0 10 0 -0 0</pose>
      </light>
    </state>
    <gui fullscreen='0'>
      <camera name='user_camera'>
        <pose frame=''>5.328 0.415093 5.16617 0 0.707644 -2.62381</pose>
        <view_controller>orbit</view_controller>
        <projection_type>perspective</projection_type>
      </camera>
    </gui>
    <audio>
      <device>default</device>
    </audio>
    <model name='living_lab_robot'>
      <link name='base_footprint'>
        <pose frame=''>0 0 0 0 -0 0</pose>
        <inertial>
          <pose frame=''>0 0 0.1746 0 -0 0</pose>
          <mass>55</mass>
          <inertia>
            <ixx>1.70049</ixx>
            <ixy>0</ixy>
            <ixz>0</ixz>
            <iyy>1.70049</iyy>
            <iyz>0</iyz>
            <izz>2.6048</izz>
          </inertia>
        </inertial>
        <collision name='base_footprint_fixed_joint_lump__base_link_collision'>
          <pose frame=''>0 0 0.0635 0 -0 0</pose>
          <geometry>
            <mesh>
              <scale>1 1 1</scale>
              <uri>/home/vision/catkin_ws/src/zipsa_robot_simulation/living_lab_robot_description/meshes/mobile_assy.dae</uri>
            </mesh>
          </geometry>
          <surface>
            <contact>
              <ode/>
            </contact>
            <friction>
              <ode>
                <mu>0</mu>
                <mu2>0</mu2>
              </ode>
              <torsional>
                <ode/>
              </torsional>
            </friction>
            <bounce/>
          </surface>
          <max_contacts>10</max_contacts>
        </collision>
        <visual name='base_footprint_fixed_joint_lump__base_link_visual'>
          <pose frame=''>0 0 0.0635 0 -0 0</pose>
          <geometry>
            <mesh>
              <scale>1 1 1</scale>
              <uri>/home/vision/catkin_ws/src/zipsa_robot_simulation/living_lab_robot_description/meshes/mobile_assy.dae</uri>
            </mesh>
          </geometry>
          <material>
            <script>
              <uri>__default__</uri>
              <name>__default__</name>
            </script>
          </material>
        </visual>
        <velocity_decay/>
        <velocity_decay/>
        <sensor name='front_hokuyo_sensor' type='ray'>
          <visualize>1</visualize>
          <update_rate>30</update_rate>
          <ray>
            <scan>
              <horizontal>
                <samples>720</samples>
                <resolution>1</resolution>
                <min_angle>-1.5</min_angle>
                <max_angle>1.5</max_angle>
              </horizontal>
              <vertical>
                <samples>1</samples>
                <min_angle>0</min_angle>
                <max_angle>0</max_angle>
              </vertical>
            </scan>
            <range>
              <min>0.15</min>
              <max>30</max>
              <resolution>0.01</resolution>
            </range>
            <noise>
              <type>gaussian</type>
              <mean>0</mean>
              <stddev>0.01</stddev>
            </noise>
          </ray>
          <plugin name='gazebo_hokuyo_controller' filename='libgazebo_ros_laser.so'>
            <topicName>front/scan</topicName>
            <frameName>front_hokuyo_link</frameName>
            <robotNamespace>/</robotNamespace>
          </plugin>
          <pose frame=''>0.27 0 0.2285 0 -0 0</pose>
        </sensor>
        <gravity>1</gravity>
        <velocity_decay/>
        <sensor name='rear_hokuyo_sensor' type='ray'>
          <visualize>1</visualize>
          <update_rate>30</update_rate>
          <ray>
            <scan>
              <horizontal>
                <samples>720</samples>
                <resolution>1</resolution>
                <min_angle>-1.5</min_angle>
                <max_angle>1.5</max_angle>
              </horizontal>
              <vertical>
                <samples>1</samples>
                <min_angle>0</min_angle>
                <max_angle>0</max_angle>
              </vertical>
            </scan>
            <range>
              <min>0.15</min>
              <max>30</max>
              <resolution>0.01</resolution>
            </range>
            <noise>
              <type>gaussian</type>
              <mean>0</mean>
              <stddev>0.01</stddev>
            </noise>
          </ray>
          <plugin name='gazebo_hokuyo_controller' filename='libgazebo_ros_laser.so'>
            <topicName>rear/scan</topicName>
            <frameName>rear_hokuyo_link</frameName>
            <robotNamespace>/</robotNamespace>
          </plugin>
          <pose frame=''>-0.27 0 0.2285 0 -0 -3.14159</pose>
        </sensor>
        <self_collide>0</self_collide>
        <enable_wind>0</enable_wind>
        <kinematic>0</kinematic>
      </link>
      <link name='body_assy'>
        <pose frame=''>0 0 0.3055 0 -0 0</pose>
        <inertial>
          <pose frame=''>0 0 0.378 0 -0 0</pose>
          <mass>30.21</mass>
          <inertia>
            <ixx>0.263797</ixx>
            <ixy>1.4e-05</ixy>
            <ixz>-0.000365</ixz>
            <iyy>0.255334</iyy>
            <iyz>-0.000303</iyz>
            <izz>0.069846</izz>
          </inertia>
        </inertial>
        <collision name='body_assy_collision'>
          <pose frame=''>0 0 0 0 -0 0</pose>
          <geometry>
            <mesh>
              <scale>1 1 1</scale>
              <uri>/home/vision/catkin_ws/src/zipsa_robot_simulation/living_lab_robot_description/meshes/body_assy.dae</uri>
            </mesh>
          </geometry>
          <max_contacts>10</max_contacts>
          <surface>
            <contact>
              <ode/>
            </contact>
            <bounce/>
            <friction>
              <torsional>
                <ode/>
              </torsional>
              <ode/>
            </friction>
          </surface>
        </collision>
        <visual name='body_assy_visual'>
          <pose frame=''>0 0 0 0 -0 0</pose>
          <geometry>
            <mesh>
              <scale>1 1 1</scale>
              <uri>/home/vision/catkin_ws/src/zipsa_robot_simulation/living_lab_robot_description/meshes/body_assy.dae</uri>
            </mesh>
          </geometry>
        </visual>
        <self_collide>0</self_collide>
        <enable_wind>0</enable_wind>
        <kinematic>0</kinematic>
      </link>
      <joint name='body_rotate_joint' type='revolute'>
        <child>body_assy</child>
        <parent>base_footprint</parent>
        <axis>
          <xyz>0 0 1</xyz>
          <limit>
            <lower>-3.49066</lower>
            <upper>3.49066</upper>
            <effort>1000</effort>
            <velocity>0.4</velocity>
          </limit>
          <dynamics>
            <spring_reference>0</spring_reference>
            <spring_stiffness>0</spring_stiffness>
          </dynamics>
          <use_parent_model_frame>1</use_parent_model_frame>
        </axis>
      </joint>
      <link name='elevation_module'>
        <pose frame=''>-0.05 0 0.9705 0 -0 0</pose>
        <inertial>
          <pose frame=''>0 0 0 0 -0 0</pose>
          <mass>10.31</mass>
          <inertia>
            <ixx>0.001422</ixx>
            <ixy>0</ixy>
            <ixz>0</ixz>
            <iyy>0.000917</iyy>
            <iyz>0</iyz>
            <izz>0.001769</izz>
          </inertia>
        </inertial>
        <collision name='elevation_module_collision'>
          <pose frame=''>0 0 0 0 -0 0</pose>
          <geometry>
            <mesh>
              <scale>1 1 1</scale>
              <uri>/home/vision/catkin_ws/src/zipsa_robot_simulation/living_lab_robot_description/meshes/elevation_module.dae</uri>
            </mesh>
          </geometry>
          <max_contacts>10</max_contacts>
          <surface>
            <contact>
              <ode/>
            </contact>
            <bounce/>
            <friction>
              <torsional>
                <ode/>
              </torsional>
              <ode/>
            </friction>
          </surface>
        </collision>
        <visual name='elevation_module_visual'>
          <pose frame=''>0 0 0 0 -0 0</pose>
          <geometry>
            <mesh>
              <scale>1 1 1</scale>
              <uri>/home/vision/catkin_ws/src/zipsa_robot_simulation/living_lab_robot_description/meshes/elevation_module.dae</uri>
            </mesh>
          </geometry>
        </visual>
        <self_collide>0</self_collide>
        <enable_wind>0</enable_wind>
        <kinematic>0</kinematic>
      </link>
      <joint name='elevation_joint' type='prismatic'>
        <child>elevation_module</child>
        <parent>body_assy</parent>
        <axis>
          <xyz>0 0 1</xyz>
          <limit>
            <lower>-0.45</lower>
            <upper>0</upper>
            <effort>100</effort>
            <velocity>0.1</velocity>
          </limit>
          <dynamics>
            <damping>0.01</damping>
            <friction>0</friction>
            <spring_reference>0</spring_reference>
            <spring_stiffness>0</spring_stiffness>
          </dynamics>
          <use_parent_model_frame>1</use_parent_model_frame>
        </axis>
      </joint>
      <link name='arm_base'>
        <pose frame=''>-0.015 0 0.9477 0 -0 0</pose>
        <inertial>
          <pose frame=''>0.0784 0 -0.0345 0 -0 0</pose>
          <mass>0.04997</mass>
          <inertia>
            <ixx>0.0007768</ixx>
            <ixy>0</ixy>
            <ixz>0</ixz>
            <iyy>0.0023504</iyy>
            <iyz>0</iyz>
            <izz>0.0020179</izz>
          </inertia>
        </inertial>
        <collision name='arm_base_collision'>
          <pose frame=''>0 0 0 0 -0 0</pose>
          <geometry>
            <mesh>
              <scale>1 1 1</scale>
              <uri>/home/vision/catkin_ws/src/zipsa_robot_simulation/living_lab_robot_description/meshes/arm_base.dae</uri>
            </mesh>
          </geometry>
          <max_contacts>10</max_contacts>
          <surface>
            <contact>
              <ode/>
            </contact>
            <bounce/>
            <friction>
              <torsional>
                <ode/>
              </torsional>
              <ode/>
            </friction>
          </surface>
        </collision>
        <visual name='arm_base_visual'>
          <pose frame=''>0 0 0 0 -0 0</pose>
          <geometry>
            <mesh>
              <scale>1 1 1</scale>
              <uri>/home/vision/catkin_ws/src/zipsa_robot_simulation/living_lab_robot_description/meshes/arm_base.dae</uri>
            </mesh>
          </geometry>
        </visual>
        <self_collide>0</self_collide>
        <enable_wind>0</enable_wind>
        <kinematic>0</kinematic>
      </link>
      <joint name='arm_base_joint' type='prismatic'>
        <child>arm_base</child>
        <parent>elevation_module</parent>
        <axis>
          <xyz>1 0 0</xyz>
          <limit>
            <lower>-0.15</lower>
            <upper>0</upper>
            <effort>50</effort>
            <velocity>0.06</velocity>
          </limit>
          <dynamics>
            <damping>0.01</damping>
            <friction>0</friction>
            <spring_reference>0</spring_reference>
            <spring_stiffness>0</spring_stiffness>
          </dynamics>
          <use_parent_model_frame>1</use_parent_model_frame>
        </axis>
      </joint>
      <link name='arm_link1'>
        <pose frame=''>0.14112 0 0.896485 0 -0 0</pose>
        <inertial>
          <pose frame=''>0.033 0 0 0 -0 0</pose>
          <mass>0.05067</mass>
          <inertia>
            <ixx>0.0021992</ixx>
            <ixy>0</ixy>
            <ixz>0</ixz>
            <iyy>0.000667</iyy>
            <iyz>0</iyz>
            <izz>0.0021992</izz>
          </inertia>
        </inertial>
        <collision name='arm_link1_collision'>
          <pose frame=''>0 0 0 0 -0 0</pose>
          <geometry>
            <mesh>
              <scale>1 1 1</scale>
              <uri>/home/vision/catkin_ws/src/zipsa_robot_simulation/living_lab_robot_description/meshes/arm_link1.dae</uri>
            </mesh>
          </geometry>
          <max_contacts>10</max_contacts>
          <surface>
            <contact>
              <ode/>
            </contact>
            <bounce/>
            <friction>
              <torsional>
                <ode/>
              </torsional>
              <ode/>
            </friction>
          </surface>
        </collision>
        <visual name='arm_link1_visual'>
          <pose frame=''>0 0 0 0 -0 0</pose>
          <geometry>
            <mesh>
              <scale>1 1 1</scale>
              <uri>/home/vision/catkin_ws/src/zipsa_robot_simulation/living_lab_robot_description/meshes/arm_link1.dae</uri>
            </mesh>
          </geometry>
        </visual>
        <self_collide>0</self_collide>
        <enable_wind>0</enable_wind>
        <kinematic>0</kinematic>
      </link>
      <joint name='arm1_joint' type='revolute'>
        <child>arm_link1</child>
        <parent>arm_base</parent>
        <axis>
          <xyz>1 0 0</xyz>
          <limit>
            <lower>-3.14159</lower>
            <upper>3.14159</upper>
            <effort>50</effort>
            <velocity>1</velocity>
          </limit>
          <dynamics>
            <damping>0.01</damping>
            <friction>0</friction>
            <spring_reference>0</spring_reference>
            <spring_stiffness>0</spring_stiffness>
          </dynamics>
          <use_parent_model_frame>1</use_parent_model_frame>
        </axis>
      </joint>
      <link name='arm_link2'>
        <pose frame=''>0.17412 0 0.896485 0 -0 0</pose>
        <inertial>
          <pose frame=''>0.1642 0 0.0083 0 -0 0</pose>
          <mass>0.09</mass>
          <inertia>
            <ixx>0.0021659</ixx>
            <ixy>0</ixy>
            <ixz>0</ixz>
            <iyy>0.0074914</iyy>
            <iyz>0</iyz>
            <izz>0.0086634</izz>
          </inertia>
        </inertial>
        <collision name='arm_link2_collision'>
          <pose frame=''>0 0 0 0 -0 0</pose>
          <geometry>
            <mesh>
              <scale>1 1 1</scale>
              <uri>/home/vision/catkin_ws/src/zipsa_robot_simulation/living_lab_robot_description/meshes/arm_link2.dae</uri>
            </mesh>
          </geometry>
          <max_contacts>10</max_contacts>
          <surface>
            <contact>
              <ode/>
            </contact>
            <bounce/>
            <friction>
              <torsional>
                <ode/>
              </torsional>
              <ode/>
            </friction>
          </surface>
        </collision>
        <visual name='arm_link2_visual'>
          <pose frame=''>0 0 0 0 -0 0</pose>
          <geometry>
            <mesh>
              <scale>1 1 1</scale>
              <uri>/home/vision/catkin_ws/src/zipsa_robot_simulation/living_lab_robot_description/meshes/arm_link2.dae</uri>
            </mesh>
          </geometry>
        </visual>
        <self_collide>0</self_collide>
        <enable_wind>0</enable_wind>
        <kinematic>0</kinematic>
      </link>
      <joint name='arm2_joint' type='revolute'>
        <child>arm_link2</child>
        <parent>arm_link1</parent>
        <axis>
          <xyz>0 1 0</xyz>
          <limit>
            <lower>-1.65806</lower>
            <upper>1.65806</upper>
            <effort>50</effort>
            <velocity>1</velocity>
          </limit>
          <dynamics>
            <damping>0.01</damping>
            <friction>0</friction>
            <spring_reference>0</spring_reference>
            <spring_stiffness>0</spring_stiffness>
          </dynamics>
          <use_parent_model_frame>1</use_parent_model_frame>
        </axis>
      </joint>
      <link name='arm_link3'>
        <pose frame=''>0.43812 0 0.926485 0 -0 0</pose>
        <inertial>
          <pose frame=''>0.1137 0 -0.0409 0 -0 0</pose>
          <mass>0.08</mass>
          <inertia>
            <ixx>0.0013151</ixx>
            <ixy>0</ixy>
            <ixz>0</ixz>
            <iyy>0.0034294</iyy>
            <iyz>0</iyz>
            <izz>0.0042325</izz>
          </inertia>
        </inertial>
        <collision name='arm_link3_collision'>
          <pose frame=''>0 0 0 0 -0 0</pose>
          <geometry>
            <mesh>
              <scale>1 1 1</scale>
              <uri>/home/vision/catkin_ws/src/zipsa_robot_simulation/living_lab_robot_description/meshes/arm_link3.dae</uri>
            </mesh>
          </geometry>
          <max_contacts>10</max_contacts>
          <surface>
            <contact>
              <ode/>
            </contact>
            <bounce/>
            <friction>
              <torsional>
                <ode/>
              </torsional>
              <ode/>
            </friction>
          </surface>
        </collision>
        <visual name='arm_link3_visual'>
          <pose frame=''>0 0 0 0 -0 0</pose>
          <geometry>
            <mesh>
              <scale>1 1 1</scale>
              <uri>/home/vision/catkin_ws/src/zipsa_robot_simulation/living_lab_robot_description/meshes/arm_link3.dae</uri>
            </mesh>
          </geometry>
        </visual>
        <self_collide>0</self_collide>
        <enable_wind>0</enable_wind>
        <kinematic>0</kinematic>
      </link>
      <joint name='arm3_joint' type='revolute'>
        <child>arm_link3</child>
        <parent>arm_link2</parent>
        <axis>
          <xyz>0 1 0</xyz>
          <limit>
            <lower>-3.14159</lower>
            <upper>0.0872665</upper>
            <effort>50</effort>
            <velocity>1</velocity>
          </limit>
          <dynamics>
            <damping>0.01</damping>
            <friction>0</friction>
            <spring_reference>0</spring_reference>
            <spring_stiffness>0</spring_stiffness>
          </dynamics>
          <use_parent_model_frame>1</use_parent_model_frame>
        </axis>
      </joint>
      <link name='arm_link4'>
        <pose frame=''>0.66912 0 0.884485 0 -0 0</pose>
        <inertial>
          <pose frame=''>0.0269 0 0 0 -0 0</pose>
          <mass>0.02697</mass>
          <inertia>
            <ixx>0.0012527</ixx>
            <ixy>0</ixy>
            <ixz>0</ixz>
            <iyy>0.0003956</iyy>
            <iyz>0</iyz>
            <izz>0.0012527</izz>
          </inertia>
        </inertial>
        <collision name='arm_link4_collision'>
          <pose frame=''>0 0 0 0 -0 0</pose>
          <geometry>
            <mesh>
              <scale>1 1 1</scale>
              <uri>/home/vision/catkin_ws/src/zipsa_robot_simulation/living_lab_robot_description/meshes/arm_link4.dae</uri>
            </mesh>
          </geometry>
          <max_contacts>10</max_contacts>
          <surface>
            <contact>
              <ode/>
            </contact>
            <bounce/>
            <friction>
              <torsional>
                <ode/>
              </torsional>
              <ode/>
            </friction>
          </surface>
        </collision>
        <visual name='arm_link4_visual'>
          <pose frame=''>0 0 0 0 -0 0</pose>
          <geometry>
            <mesh>
              <scale>1 1 1</scale>
              <uri>/home/vision/catkin_ws/src/zipsa_robot_simulation/living_lab_robot_description/meshes/arm_link4.dae</uri>
            </mesh>
          </geometry>
        </visual>
        <self_collide>0</self_collide>
        <enable_wind>0</enable_wind>
        <kinematic>0</kinematic>
      </link>
      <joint name='arm4_joint' type='revolute'>
        <child>arm_link4</child>
        <parent>arm_link3</parent>
        <axis>
          <xyz>1 0 0</xyz>
          <limit>
            <lower>-3.14159</lower>
            <upper>3.14159</upper>
            <effort>50</effort>
            <velocity>1</velocity>
          </limit>
          <dynamics>
            <damping>0.01</damping>
            <friction>0</friction>
            <spring_reference>0</spring_reference>
            <spring_stiffness>0</spring_stiffness>
          </dynamics>
          <use_parent_model_frame>1</use_parent_model_frame>
        </axis>
      </joint>
      <link name='arm_link5'>
        <pose frame=''>0.69612 0 0.884485 0 -0 0</pose>
        <inertial>
          <pose frame=''>0.0667 0 -0.0005 0 -0 0</pose>
          <mass>0.03885</mass>
          <inertia>
            <ixx>0.0005947</ixx>
            <ixy>0</ixy>
            <ixz>0</ixz>
            <iyy>0.0005919</iyy>
            <iyz>0</iyz>
            <izz>0.001005</izz>
          </inertia>
        </inertial>
        <collision name='arm_link5_collision'>
          <pose frame=''>0 0 0 0 -0 0</pose>
          <geometry>
            <mesh>
              <scale>1 1 1</scale>
              <uri>/home/vision/catkin_ws/src/zipsa_robot_simulation/living_lab_robot_description/meshes/arm_link5.dae</uri>
            </mesh>
          </geometry>
          <max_contacts>10</max_contacts>
          <surface>
            <contact>
              <ode/>
            </contact>
            <bounce/>
            <friction>
              <torsional>
                <ode/>
              </torsional>
              <ode/>
            </friction>
          </surface>
        </collision>
        <visual name='arm_link5_visual'>
          <pose frame=''>0 0 0 0 -0 0</pose>
          <geometry>
            <mesh>
              <scale>1 1 1</scale>
              <uri>/home/vision/catkin_ws/src/zipsa_robot_simulation/living_lab_robot_description/meshes/arm_link5.dae</uri>
            </mesh>
          </geometry>
        </visual>
        <self_collide>0</self_collide>
        <enable_wind>0</enable_wind>
        <kinematic>0</kinematic>
      </link>
      <joint name='arm5_joint' type='revolute'>
        <child>arm_link5</child>
        <parent>arm_link4</parent>
        <axis>
          <xyz>0 1 0</xyz>
          <limit>
            <lower>-1.65806</lower>
            <upper>1.65806</upper>
            <effort>50</effort>
            <velocity>1</velocity>
          </limit>
          <dynamics>
            <damping>0.01</damping>
            <friction>0</friction>
            <spring_reference>0</spring_reference>
            <spring_stiffness>0</spring_stiffness>
          </dynamics>
          <use_parent_model_frame>1</use_parent_model_frame>
        </axis>
      </joint>
      <link name='arm_link6'>
        <pose frame=''>0.81912 0 0.884485 0 -0 0</pose>
        <inertial>
          <pose frame=''>0.0299 0 0.00108 0 -0 0</pose>
          <mass>0.3948</mass>
          <inertia>
            <ixx>0.000306104</ixx>
            <ixy>0</ixy>
            <ixz>-1.36273e-07</ixz>
            <iyy>0.000217758</iyy>
            <iyz>0</iyz>
            <izz>0.000284753</izz>
          </inertia>
        </inertial>
        <collision name='arm_link6_collision'>
          <pose frame=''>0 0 0 0 -0 0</pose>
          <geometry>
            <mesh>
              <scale>1 1 1</scale>
              <uri>/home/vision/catkin_ws/src/zipsa_robot_simulation/living_lab_robot_description/meshes/arm_link6.dae</uri>
            </mesh>
          </geometry>
          <max_contacts>10</max_contacts>
          <surface>
            <contact>
              <ode/>
            </contact>
            <bounce/>
            <friction>
              <torsional>
                <ode/>
              </torsional>
              <ode/>
            </friction>
          </surface>
        </collision>
        <collision name='arm_link6_fixed_joint_lump__gripper_base_link_collision_1'>
          <pose frame=''>0 0 0 0 -0 0</pose>
          <geometry>
            <mesh>
              <scale>1 1 1</scale>
              <uri>/home/vision/catkin_ws/src/robotis_gripper/robotis_gripper_description/meshes/gripper_base.dae</uri>
            </mesh>
          </geometry>
          <max_contacts>10</max_contacts>
          <surface>
            <contact>
              <ode/>
            </contact>
            <bounce/>
            <friction>
              <torsional>
                <ode/>
              </torsional>
              <ode/>
            </friction>
          </surface>
        </collision>
        <visual name='arm_link6_visual'>
          <pose frame=''>0 0 0 0 -0 0</pose>
          <geometry>
            <mesh>
              <scale>1 1 1</scale>
              <uri>/home/vision/catkin_ws/src/zipsa_robot_simulation/living_lab_robot_description/meshes/arm_link6.dae</uri>
            </mesh>
          </geometry>
        </visual>
        <visual name='arm_link6_fixed_joint_lump__gripper_base_link_visual_1'>
          <pose frame=''>0 0 0 0 -0 0</pose>
          <geometry>
            <mesh>
              <scale>1 1 1</scale>
              <uri>/home/vision/catkin_ws/src/robotis_gripper/robotis_gripper_description/meshes/gripper_base.dae</uri>
            </mesh>
          </geometry>
        </visual>
        <self_collide>0</self_collide>
        <enable_wind>0</enable_wind>
        <kinematic>0</kinematic>
      </link>
      <joint name='arm6_joint' type='revolute'>
        <child>arm_link6</child>
        <parent>arm_link5</parent>
        <axis>
          <xyz>1 0 0</xyz>
          <limit>
            <lower>-3.14159</lower>
            <upper>3.14159</upper>
            <effort>50</effort>
            <velocity>1</velocity>
          </limit>
          <dynamics>
            <damping>0.01</damping>
            <friction>0</friction>
            <spring_reference>0</spring_reference>
            <spring_stiffness>0</spring_stiffness>
          </dynamics>
          <use_parent_model_frame>1</use_parent_model_frame>
        </axis>
      </joint>
      <link name='gripper_l_inner_link'>
        <pose frame=''>0.86712 0.008 0.884485 0 -0 0</pose>
        <inertial>
          <pose frame=''>0.02966 -0.00035 2e-05 0 -0 0</pose>
          <mass>0.0158</mass>
          <inertia>
            <ixx>2e-06</ixx>
            <ixy>0</ixy>
            <ixz>0</ixz>
            <iyy>6e-06</iyy>
            <iyz>0</iyz>
            <izz>4e-06</izz>
          </inertia>
        </inertial>
        <collision name='gripper_l_inner_link_collision'>
          <pose frame=''>0 0 0 0 -0 0</pose>
          <geometry>
            <mesh>
              <scale>1 1 1</scale>
              <uri>/home/vision/catkin_ws/src/robotis_gripper/robotis_gripper_description/meshes/inner_link.dae</uri>
            </mesh>
          </geometry>
          <max_contacts>10</max_contacts>
          <surface>
            <contact>
              <ode/>
            </contact>
            <bounce/>
            <friction>
              <torsional>
                <ode/>
              </torsional>
              <ode/>
            </friction>
          </surface>
        </collision>
        <visual name='gripper_l_inner_link_visual'>
          <pose frame=''>0 0 0 0 -0 0</pose>
          <geometry>
            <mesh>
              <scale>1 1 1</scale>
              <uri>/home/vision/catkin_ws/src/robotis_gripper/robotis_gripper_description/meshes/inner_link.dae</uri>
            </mesh>
          </geometry>
        </visual>
        <self_collide>0</self_collide>
        <enable_wind>0</enable_wind>
        <kinematic>0</kinematic>
      </link>
      <joint name='gripper_joint' type='revolute'>
        <child>gripper_l_inner_link</child>
        <parent>arm_link6</parent>
        <axis>
          <xyz>0 0 1</xyz>
          <limit>
            <lower>-0.075</lower>
            <upper>1.2217</upper>
            <effort>1000</effort>
            <velocity>1</velocity>
          </limit>
          <dynamics>
            <spring_reference>0</spring_reference>
            <spring_stiffness>0</spring_stiffness>
          </dynamics>
          <use_parent_model_frame>1</use_parent_model_frame>
        </axis>
      </joint>
      <link name='gripper_l_finger_link'>
        <pose frame=''>0.92412 0.008 0.884485 0 -0 0</pose>
        <inertial>
          <pose frame=''>0.00958 0.00643 0 0 -0 0</pose>
          <mass>0.0257</mass>
          <inertia>
            <ixx>3e-06</ixx>
            <ixy>2e-06</ixy>
            <ixz>0</ixz>
            <iyy>8e-06</iyy>
            <iyz>0</iyz>
            <izz>7e-06</izz>
          </inertia>
        </inertial>
        <collision name='gripper_l_finger_link_collision'>
          <pose frame=''>0 0 0 0 -0 0</pose>
          <geometry>
            <mesh>
              <scale>1 1 1</scale>
              <uri>/home/vision/catkin_ws/src/robotis_gripper/robotis_gripper_description/meshes/finger.dae</uri>
            </mesh>
          </geometry>
          <max_contacts>10</max_contacts>
          <surface>
            <contact>
              <ode/>
            </contact>
            <bounce/>
            <friction>
              <torsional>
                <ode/>
              </torsional>
              <ode/>
            </friction>
          </surface>
        </collision>
        <visual name='gripper_l_finger_link_visual'>
          <pose frame=''>0 0 0 0 -0 0</pose>
          <geometry>
            <mesh>
              <scale>1 1 1</scale>
              <uri>/home/vision/catkin_ws/src/robotis_gripper/robotis_gripper_description/meshes/finger.dae</uri>
            </mesh>
          </geometry>
        </visual>
        <self_collide>0</self_collide>
        <enable_wind>0</enable_wind>
        <kinematic>0</kinematic>
      </link>
      <joint name='gripper_l_finger_joint' type='revolute'>
        <child>gripper_l_finger_link</child>
        <parent>gripper_l_inner_link</parent>
        <axis>
          <xyz>0 0 1</xyz>
          <limit>
            <lower>-1.5707</lower>
            <upper>1.5707</upper>
            <effort>1000</effort>
            <velocity>1</velocity>
          </limit>
          <dynamics>
            <spring_reference>0</spring_reference>
            <spring_stiffness>0</spring_stiffness>
          </dynamics>
          <use_parent_model_frame>1</use_parent_model_frame>
        </axis>
      </joint>
      <link name='gripper_l_outer_link'>
        <pose frame=''>0.85652 0.0186 0.884485 0 -0 0</pose>
        <inertial>
          <pose frame=''>0.01616 0.02092 0.00067 0 -0 0</pose>
          <mass>0.013</mass>
          <inertia>
            <ixx>1e-06</ixx>
            <ixy>-1e-06</ixy>
            <ixz>0</ixz>
            <iyy>6e-06</iyy>
            <iyz>0</iyz>
            <izz>6e-06</izz>
          </inertia>
        </inertial>
        <collision name='gripper_l_outer_link_collision'>
          <pose frame=''>0 0 0 0 -0 0</pose>
          <geometry>
            <mesh>
              <scale>1 1 1</scale>
              <uri>/home/vision/catkin_ws/src/robotis_gripper/robotis_gripper_description/meshes/l_outer_link.dae</uri>
            </mesh>
          </geometry>
          <max_contacts>10</max_contacts>
          <surface>
            <contact>
              <ode/>
            </contact>
            <bounce/>
            <friction>
              <torsional>
                <ode/>
              </torsional>
              <ode/>
            </friction>
          </surface>
        </collision>
        <visual name='gripper_l_outer_link_visual'>
          <pose frame=''>0 0 0 0 -0 0</pose>
          <geometry>
            <mesh>
              <scale>1 1 1</scale>
              <uri>/home/vision/catkin_ws/src/robotis_gripper/robotis_gripper_description/meshes/l_outer_link.dae</uri>
            </mesh>
          </geometry>
        </visual>
        <self_collide>0</self_collide>
        <enable_wind>0</enable_wind>
        <kinematic>0</kinematic>
      </link>
      <joint name='gripper_l_outer_joint' type='revolute'>
        <child>gripper_l_outer_link</child>
        <parent>arm_link6</parent>
        <axis>
          <xyz>0 0 1</xyz>
          <limit>
            <lower>-1.5707</lower>
            <upper>1.5707</upper>
            <effort>1000</effort>
            <velocity>1</velocity>
          </limit>
          <dynamics>
            <spring_reference>0</spring_reference>
            <spring_stiffness>0</spring_stiffness>
          </dynamics>
          <use_parent_model_frame>1</use_parent_model_frame>
        </axis>
      </joint>
      <link name='gripper_r_inner_link'>
        <pose frame=''>0.86712 -0.008 0.884485 0 -0 0</pose>
        <inertial>
          <pose frame=''>0.02966 -0.00035 2e-05 -3.14159 -0 0</pose>
          <mass>0.0158</mass>
          <inertia>
            <ixx>2e-06</ixx>
            <ixy>0</ixy>
            <ixz>0</ixz>
            <iyy>6e-06</iyy>
            <iyz>0</iyz>
            <izz>4e-06</izz>
          </inertia>
        </inertial>
        <collision name='gripper_r_inner_link_collision'>
          <pose frame=''>0 0 0 -3.14159 -0 0</pose>
          <geometry>
            <mesh>
              <scale>1 1 1</scale>
              <uri>/home/vision/catkin_ws/src/robotis_gripper/robotis_gripper_description/meshes/inner_link.dae</uri>
            </mesh>
          </geometry>
          <max_contacts>10</max_contacts>
          <surface>
            <contact>
              <ode/>
            </contact>
            <bounce/>
            <friction>
              <torsional>
                <ode/>
              </torsional>
              <ode/>
            </friction>
          </surface>
        </collision>
        <visual name='gripper_r_inner_link_visual'>
          <pose frame=''>0 0 0 -3.14159 -0 0</pose>
          <geometry>
            <mesh>
              <scale>1 1 1</scale>
              <uri>/home/vision/catkin_ws/src/robotis_gripper/robotis_gripper_description/meshes/inner_link.dae</uri>
            </mesh>
          </geometry>
        </visual>
        <self_collide>0</self_collide>
        <enable_wind>0</enable_wind>
        <kinematic>0</kinematic>
      </link>
      <joint name='gripper_r_inner_joint' type='revolute'>
        <child>gripper_r_inner_link</child>
        <parent>arm_link6</parent>
        <axis>
          <xyz>0 0 1</xyz>
          <limit>
            <lower>-1.5707</lower>
            <upper>1.5707</upper>
            <effort>1000</effort>
            <velocity>1</velocity>
          </limit>
          <dynamics>
            <spring_reference>0</spring_reference>
            <spring_stiffness>0</spring_stiffness>
          </dynamics>
          <use_parent_model_frame>1</use_parent_model_frame>
        </axis>
      </joint>
      <link name='gripper_r_finger_link'>
        <pose frame=''>0.92412 -0.008 0.884485 0 -0 0</pose>
        <inertial>
          <pose frame=''>0.00958 -0.00643 0 -3.14159 -0 0</pose>
          <mass>0.0257</mass>
          <inertia>
            <ixx>3e-06</ixx>
            <ixy>2e-06</ixy>
            <ixz>0</ixz>
            <iyy>8e-06</iyy>
            <iyz>0</iyz>
            <izz>7e-06</izz>
          </inertia>
        </inertial>
        <collision name='gripper_r_finger_link_collision'>
          <pose frame=''>0 0 0 -3.14159 -0 0</pose>
          <geometry>
            <mesh>
              <scale>1 1 1</scale>
              <uri>/home/vision/catkin_ws/src/robotis_gripper/robotis_gripper_description/meshes/finger.dae</uri>
            </mesh>
          </geometry>
          <max_contacts>10</max_contacts>
          <surface>
            <contact>
              <ode/>
            </contact>
            <bounce/>
            <friction>
              <torsional>
                <ode/>
              </torsional>
              <ode/>
            </friction>
          </surface>
        </collision>
        <visual name='gripper_r_finger_link_visual'>
          <pose frame=''>0 0 0 -3.14159 -0 0</pose>
          <geometry>
            <mesh>
              <scale>1 1 1</scale>
              <uri>/home/vision/catkin_ws/src/robotis_gripper/robotis_gripper_description/meshes/finger.dae</uri>
            </mesh>
          </geometry>
        </visual>
        <self_collide>0</self_collide>
        <enable_wind>0</enable_wind>
        <kinematic>0</kinematic>
      </link>
      <joint name='gripper_r_finger_joint' type='revolute'>
        <child>gripper_r_finger_link</child>
        <parent>gripper_r_inner_link</parent>
        <axis>
          <xyz>0 0 1</xyz>
          <limit>
            <lower>-1.5707</lower>
            <upper>1.5707</upper>
            <effort>1000</effort>
            <velocity>1</velocity>
          </limit>
          <dynamics>
            <spring_reference>0</spring_reference>
            <spring_stiffness>0</spring_stiffness>
          </dynamics>
          <use_parent_model_frame>1</use_parent_model_frame>
        </axis>
      </joint>
      <link name='gripper_r_outer_link'>
        <pose frame=''>0.85652 -0.0186 0.884485 0 -0 0</pose>
        <inertial>
          <pose frame=''>0.01616 -0.02092 0.00065 0 -0 0</pose>
          <mass>0.013</mass>
          <inertia>
            <ixx>1e-06</ixx>
            <ixy>1e-06</ixy>
            <ixz>0</ixz>
            <iyy>6e-06</iyy>
            <iyz>0</iyz>
            <izz>6e-06</izz>
          </inertia>
        </inertial>
        <collision name='gripper_r_outer_link_collision'>
          <pose frame=''>0 0 0 0 -0 0</pose>
          <geometry>
            <mesh>
              <scale>1 1 1</scale>
              <uri>/home/vision/catkin_ws/src/robotis_gripper/robotis_gripper_description/meshes/r_outer_link.dae</uri>
            </mesh>
          </geometry>
          <max_contacts>10</max_contacts>
          <surface>
            <contact>
              <ode/>
            </contact>
            <bounce/>
            <friction>
              <torsional>
                <ode/>
              </torsional>
              <ode/>
            </friction>
          </surface>
        </collision>
        <visual name='gripper_r_outer_link_visual'>
          <pose frame=''>0 0 0 0 -0 0</pose>
          <geometry>
            <mesh>
              <scale>1 1 1</scale>
              <uri>/home/vision/catkin_ws/src/robotis_gripper/robotis_gripper_description/meshes/r_outer_link.dae</uri>
            </mesh>
          </geometry>
        </visual>
        <self_collide>0</self_collide>
        <enable_wind>0</enable_wind>
        <kinematic>0</kinematic>
      </link>
      <joint name='gripper_r_outer_joint' type='revolute'>
        <child>gripper_r_outer_link</child>
        <parent>arm_link6</parent>
        <axis>
          <xyz>0 0 1</xyz>
          <limit>
            <lower>-1.5707</lower>
            <upper>1.5707</upper>
            <effort>1000</effort>
            <velocity>1</velocity>
          </limit>
          <dynamics>
            <spring_reference>0</spring_reference>
            <spring_stiffness>0</spring_stiffness>
          </dynamics>
          <use_parent_model_frame>1</use_parent_model_frame>
        </axis>
      </joint>
      <link name='head_assy'>
        <pose frame=''>0 0 1.2885 0 -0 0</pose>
        <inertial>
          <pose frame=''>0 0 -0.1224 0 -0 0</pose>
          <mass>16.5454</mass>
          <inertia>
            <ixx>0.085366</ixx>
            <ixy>0</ixy>
            <ixz>0</ixz>
            <iyy>0.085366</iyy>
            <iyz>0</iyz>
            <izz>0.105357</izz>
          </inertia>
        </inertial>
        <collision name='head_assy_collision'>
          <pose frame=''>0 0 0 0 -0 0</pose>
          <geometry>
            <mesh>
              <scale>1 1 1</scale>
              <uri>/home/vision/catkin_ws/src/zipsa_robot_simulation/living_lab_robot_description/meshes/head_assy.dae</uri>
            </mesh>
          </geometry>
          <max_contacts>10</max_contacts>
          <surface>
            <contact>
              <ode/>
            </contact>
            <bounce/>
            <friction>
              <torsional>
                <ode/>
              </torsional>
              <ode/>
            </friction>
          </surface>
        </collision>
        <visual name='head_assy_visual'>
          <pose frame=''>0 0 0 0 -0 0</pose>
          <geometry>
            <mesh>
              <scale>1 1 1</scale>
              <uri>/home/vision/catkin_ws/src/zipsa_robot_simulation/living_lab_robot_description/meshes/head_assy.dae</uri>
            </mesh>
          </geometry>
        </visual>
        <self_collide>0</self_collide>
        <enable_wind>0</enable_wind>
        <kinematic>0</kinematic>
      </link>
      <joint name='head_pan_joint' type='revolute'>
        <child>head_assy</child>
        <parent>body_assy</parent>
        <axis>
          <xyz>0 0 1</xyz>
          <limit>
            <lower>-4.71239</lower>
            <upper>4.71239</upper>
            <effort>1000</effort>
            <velocity>2</velocity>
          </limit>
          <dynamics>
            <spring_reference>0</spring_reference>
            <spring_stiffness>0</spring_stiffness>
          </dynamics>
          <use_parent_model_frame>1</use_parent_model_frame>
        </axis>
      </joint>
      <link name='head_screen'>
        <pose frame=''>0.101 0 1.1765 0 -0 0</pose>
        <inertial>
          <pose frame=''>0.014478 0 -0.04549 0 -0 0</pose>
          <mass>10.1867</mass>
          <inertia>
            <ixx>0.000811</ixx>
            <ixy>0</ixy>
            <ixz>1.2e-05</ixz>
            <iyy>0.000271</iyy>
            <iyz>0</iyz>
            <izz>0.000576</izz>
          </inertia>
        </inertial>
        <collision name='head_screen_collision'>
          <pose frame=''>0 0 0 0 -0 0</pose>
          <geometry>
            <mesh>
              <scale>1 1 1</scale>
              <uri>/home/vision/catkin_ws/src/zipsa_robot_simulation/living_lab_robot_description/meshes/head_screen.dae</uri>
            </mesh>
          </geometry>
          <max_contacts>10</max_contacts>
          <surface>
            <contact>
              <ode/>
            </contact>
            <bounce/>
            <friction>
              <torsional>
                <ode/>
              </torsional>
              <ode/>
            </friction>
          </surface>
        </collision>
        <visual name='head_screen_visual'>
          <pose frame=''>0 0 0 0 -0 0</pose>
          <geometry>
            <mesh>
              <scale>1 1 1</scale>
              <uri>/home/vision/catkin_ws/src/zipsa_robot_simulation/living_lab_robot_description/meshes/head_screen.dae</uri>
            </mesh>
          </geometry>
        </visual>
        <self_collide>0</self_collide>
        <enable_wind>0</enable_wind>
        <kinematic>0</kinematic>
      </link>
      <joint name='head_screen_tilt_joint' type='revolute'>
        <child>head_screen</child>
        <parent>head_assy</parent>
        <axis>
          <xyz>0 1 0</xyz>
          <limit>
            <lower>-0.174533</lower>
            <upper>0.0872665</upper>
            <effort>1000</effort>
            <velocity>2</velocity>
          </limit>
          <dynamics>
            <spring_reference>0</spring_reference>
            <spring_stiffness>0</spring_stiffness>
          </dynamics>
          <use_parent_model_frame>1</use_parent_model_frame>
        </axis>
      </joint>
      <link name='head_tilt_unit'>
        <pose frame=''>0.098 0 1.2725 0 -0 0</pose>
        <inertial>
          <pose frame=''>-0.097561 6.1e-05 0.057523 0 -0 0</pose>
          <mass>20.6121</mass>
          <inertia>
            <ixx>0.026307</ixx>
            <ixy>-0.000157954</ixy>
            <ixz>0.000240235</ixz>
            <iyy>0.0240382</iyy>
            <iyz>3.3419e-05</iyz>
            <izz>0.0459227</izz>
          </inertia>
        </inertial>
        <collision name='head_tilt_unit_collision'>
          <pose frame=''>0 0 0 0 -0 0</pose>
          <geometry>
            <mesh>
              <scale>1 1 1</scale>
              <uri>/home/vision/catkin_ws/src/zipsa_robot_simulation/living_lab_robot_description/meshes/head_tilt_unit.dae</uri>
            </mesh>
          </geometry>
          <max_contacts>10</max_contacts>
          <surface>
            <contact>
              <ode/>
            </contact>
            <bounce/>
            <friction>
              <torsional>
                <ode/>
              </torsional>
              <ode/>
            </friction>
          </surface>
        </collision>
        <collision name='head_tilt_unit_fixed_joint_lump__camera_link_collision_1'>
          <pose frame=''>0.0278 0 0.031 0 -0 0</pose>
          <geometry>
            <box>
              <size>0.02505 0.09 0.025</size>
            </box>
          </geometry>
          <surface>
            <contact>
              <ode/>
            </contact>
            <friction>
              <ode/>
              <torsional>
                <ode/>
              </torsional>
            </friction>
            <bounce/>
          </surface>
          <max_contacts>10</max_contacts>
        </collision>
        <visual name='head_tilt_unit_visual'>
          <pose frame=''>0 0 0 0 -0 0</pose>
          <geometry>
            <mesh>
              <scale>1 1 1</scale>
              <uri>/home/vision/catkin_ws/src/zipsa_robot_simulation/living_lab_robot_description/meshes/head_tilt_unit.dae</uri>
            </mesh>
          </geometry>
        </visual>
        <visual name='head_tilt_unit_fixed_joint_lump__camera_link_visual_1'>
          <pose frame=''>0.0321 0 0.031 1.5708 -0 1.5708</pose>
          <geometry>
            <mesh>
              <scale>1 1 1</scale>
              <uri>/home/vision/catkin_ws/src/realsense-ros/realsense2_description/meshes/d435.dae</uri>
            </mesh>
          </geometry>
          <material>
            <script>
              <uri>__default__</uri>
              <name>__default__</name>
            </script>
          </material>
        </visual>
        <gravity>1</gravity>
        <velocity_decay/>
        <sensor name='camera' type='depth'>
          <always_on>1</always_on>
          <update_rate>30</update_rate>
          <camera name='__default__'>
            <horizontal_fov>1.0472</horizontal_fov>
            <image>
              <format>R8G8B8</format>
              <width>640</width>
              <height>480</height>
            </image>
            <clip>
              <near>0.05</near>
              <far>8</far>
            </clip>
          </camera>
          <plugin name='kinect_camera_controller' filename='libgazebo_ros_openni_kinect.so'>
            <cameraName>camera</cameraName>
            <alwaysOn>1</alwaysOn>
            <updateRate>30</updateRate>
            <imageTopicName>rgb/image_raw</imageTopicName>
            <depthImageTopicName>depth_registered/image_raw</depthImageTopicName>
            <pointCloudTopicName>depth_registered/points</pointCloudTopicName>
            <cameraInfoTopicName>rgb/camera_info</cameraInfoTopicName>
            <depthImageCameraInfoTopicName>depth_registered/camera_info</depthImageCameraInfoTopicName>
            <frameName>camera_depth_optical_frame</frameName>
            <baseline>0.1</baseline>
            <distortion_k1>0.0</distortion_k1>
            <distortion_k2>0.0</distortion_k2>
            <distortion_k3>0.0</distortion_k3>
            <distortion_t1>0.0</distortion_t1>
            <distortion_t2>0.0</distortion_t2>
            <pointCloudCutoff>0.4</pointCloudCutoff>
            <robotNamespace>/</robotNamespace>
          </plugin>
          <pose frame=''>0.0278 0.0175 0.031 0 -0 0</pose>
        </sensor>
        <self_collide>0</self_collide>
        <enable_wind>0</enable_wind>
        <kinematic>0</kinematic>
      </link>
      <joint name='head_tilt_joint' type='revolute'>
        <child>head_tilt_unit</child>
        <parent>head_assy</parent>
        <axis>
          <xyz>0 1 0</xyz>
          <limit>
            <lower>0</lower>
            <upper>0.698132</upper>
            <effort>1000</effort>
            <velocity>0.2</velocity>
          </limit>
          <dynamics>
            <spring_reference>0</spring_reference>
            <spring_stiffness>0</spring_stiffness>
          </dynamics>
          <use_parent_model_frame>1</use_parent_model_frame>
        </axis>
      </joint>
      <link name='omni_wheel_1'>
        <pose frame=''>0.141 0.244219 0.0635 0 0 -0.523599</pose>
        <inertial>
          <pose frame=''>0 -0.0015 0 0 -0 0</pose>
          <mass>0.42</mass>
          <inertia>
            <ixx>0.000562</ixx>
            <ixy>0</ixy>
            <ixz>0</ixz>
            <iyy>0.000884</iyy>
            <iyz>0</iyz>
            <izz>0.000562</izz>
          </inertia>
        </inertial>
        <collision name='omni_wheel_1_collision'>
          <pose frame=''>0 0 0 0 -0 0</pose>
          <geometry>
            <sphere>
              <radius>0.065</radius>
            </sphere>
          </geometry>
          <surface>
            <contact>
              <ode/>
            </contact>
            <friction>
              <ode>
                <mu>0</mu>
              </ode>
              <torsional>
                <ode/>
              </torsional>
            </friction>
            <bounce/>
          </surface>
          <max_contacts>10</max_contacts>
        </collision>
        <visual name='omni_wheel_1_visual'>
          <pose frame=''>0 0 0 0 -0 0</pose>
          <geometry>
            <mesh>
              <scale>1 1 1</scale>
              <uri>/home/vision/catkin_ws/src/zipsa_robot_simulation/living_lab_robot_description/meshes/omni_wheel.dae</uri>
            </mesh>
          </geometry>
          <material>
            <script>
              <uri>__default__</uri>
              <name>__default__</name>
            </script>
          </material>
        </visual>
        <gravity>1</gravity>
        <velocity_decay/>
        <self_collide>0</self_collide>
        <enable_wind>0</enable_wind>
        <kinematic>0</kinematic>
      </link>
      <joint name='omni_wheel_1_joint' type='revolute'>
        <child>omni_wheel_1</child>
        <parent>base_footprint</parent>
        <axis>
          <xyz>0.5 0.866025 0</xyz>
          <limit>
            <lower>-1e+16</lower>
            <upper>1e+16</upper>
          </limit>
          <dynamics>
            <spring_reference>0</spring_reference>
            <spring_stiffness>0</spring_stiffness>
          </dynamics>
          <use_parent_model_frame>1</use_parent_model_frame>
        </axis>
      </joint>
      <link name='omni_wheel_2'>
        <pose frame=''>-0.282 0 0.0635 0 -0 1.5708</pose>
        <inertial>
          <pose frame=''>0 -0.0015 0 0 -0 0</pose>
          <mass>0.42</mass>
          <inertia>
            <ixx>0.000562</ixx>
            <ixy>0</ixy>
            <ixz>0</ixz>
            <iyy>0.000884</iyy>
            <iyz>0</iyz>
            <izz>0.000562</izz>
          </inertia>
        </inertial>
        <collision name='omni_wheel_2_collision'>
          <pose frame=''>0 0 0 0 -0 0</pose>
          <geometry>
            <sphere>
              <radius>0.065</radius>
            </sphere>
          </geometry>
          <surface>
            <contact>
              <ode/>
            </contact>
            <friction>
              <ode>
                <mu>0</mu>
              </ode>
              <torsional>
                <ode/>
              </torsional>
            </friction>
            <bounce/>
          </surface>
          <max_contacts>10</max_contacts>
        </collision>
        <visual name='omni_wheel_2_visual'>
          <pose frame=''>0 0 0 0 -0 0</pose>
          <geometry>
            <mesh>
              <scale>1 1 1</scale>
              <uri>/home/vision/catkin_ws/src/zipsa_robot_simulation/living_lab_robot_description/meshes/omni_wheel.dae</uri>
            </mesh>
          </geometry>
          <material>
            <script>
              <uri>__default__</uri>
              <name>__default__</name>
            </script>
          </material>
        </visual>
        <gravity>1</gravity>
        <velocity_decay/>
        <self_collide>0</self_collide>
        <enable_wind>0</enable_wind>
        <kinematic>0</kinematic>
      </link>
      <joint name='omni_wheel_2_joint' type='revolute'>
        <child>omni_wheel_2</child>
        <parent>base_footprint</parent>
        <axis>
          <xyz>-1 0 0</xyz>
          <limit>
            <lower>-1e+16</lower>
            <upper>1e+16</upper>
          </limit>
          <dynamics>
            <spring_reference>0</spring_reference>
            <spring_stiffness>0</spring_stiffness>
          </dynamics>
          <use_parent_model_frame>1</use_parent_model_frame>
        </axis>
      </joint>
      <link name='omni_wheel_3'>
        <pose frame=''>0.141 -0.244219 0.0635 0 0 -2.61799</pose>
        <inertial>
          <pose frame=''>0 -0.0015 0 0 -0 0</pose>
          <mass>0.42</mass>
          <inertia>
            <ixx>0.000562</ixx>
            <ixy>0</ixy>
            <ixz>0</ixz>
            <iyy>0.000884</iyy>
            <iyz>0</iyz>
            <izz>0.000562</izz>
          </inertia>
        </inertial>
        <collision name='omni_wheel_3_collision'>
          <pose frame=''>0 0 0 0 -0 0</pose>
          <geometry>
            <sphere>
              <radius>0.065</radius>
            </sphere>
          </geometry>
          <surface>
            <contact>
              <ode/>
            </contact>
            <friction>
              <ode>
                <mu>0</mu>
              </ode>
              <torsional>
                <ode/>
              </torsional>
            </friction>
            <bounce/>
          </surface>
          <max_contacts>10</max_contacts>
        </collision>
        <visual name='omni_wheel_3_visual'>
          <pose frame=''>0 0 0 0 -0 0</pose>
          <geometry>
            <mesh>
              <scale>1 1 1</scale>
              <uri>/home/vision/catkin_ws/src/zipsa_robot_simulation/living_lab_robot_description/meshes/omni_wheel.dae</uri>
            </mesh>
          </geometry>
          <material>
            <script>
              <uri>__default__</uri>
              <name>__default__</name>
            </script>
          </material>
        </visual>
        <gravity>1</gravity>
        <velocity_decay/>
        <self_collide>0</self_collide>
        <enable_wind>0</enable_wind>
        <kinematic>0</kinematic>
      </link>
      <joint name='omni_wheel_3_joint' type='revolute'>
        <child>omni_wheel_3</child>
        <parent>base_footprint</parent>
        <axis>
          <xyz>0.5 -0.866025 0</xyz>
          <limit>
            <lower>-1e+16</lower>
            <upper>1e+16</upper>
          </limit>
          <dynamics>
            <spring_reference>0</spring_reference>
            <spring_stiffness>0</spring_stiffness>
          </dynamics>
          <use_parent_model_frame>1</use_parent_model_frame>
        </axis>
      </joint>
      <plugin name='gazebo_ros_control' filename='libgazebo_ros_control.so'>
        <robotNamespace/>
        <robotSimType>gazebo_ros_control/DefaultRobotHWSim</robotSimType>
      </plugin>
      <plugin name='planar_controller' filename='libgazebo_ros_planar_move.so'>
        <commandTopic>cmd_vel</commandTopic>
        <odometryTopic>odom</odometryTopic>
        <odometryFrame>odom</odometryFrame>
        <odometryRate>50.0</odometryRate>
        <robotBaseFrame>base_footprint</robotBaseFrame>
        <robotNamespace>/</robotNamespace>
      </plugin>
      <plugin name='mimic_gripper_r_inner_joint' filename='libgazebo_mimic_joint_plugin.so'>
        <joint>gripper_joint</joint>
        <mimicJoint>gripper_r_inner_joint</mimicJoint>
        <multiplier>-1.0</multiplier>
        <offset>0.0</offset>
        <robotNamespace>/</robotNamespace>
      </plugin>
      <plugin name='mimic_gripper_l_outer_joint' filename='libgazebo_mimic_joint_plugin.so'>
        <joint>gripper_joint</joint>
        <mimicJoint>gripper_l_outer_joint</mimicJoint>
        <multiplier>1.0</multiplier>
        <offset>-0.405</offset>
        <robotNamespace>/</robotNamespace>
      </plugin>
      <plugin name='mimic_gripper_r_outer_joint' filename='libgazebo_mimic_joint_plugin.so'>
        <joint>gripper_joint</joint>
        <mimicJoint>gripper_r_outer_joint</mimicJoint>
        <multiplier>-1.0</multiplier>
        <offset>0.405</offset>
        <robotNamespace>/</robotNamespace>
      </plugin>
      <plugin name='mimic_gripper_l_finger_joint' filename='libgazebo_mimic_joint_plugin.so'>
        <joint>gripper_joint</joint>
        <mimicJoint>gripper_l_finger_joint</mimicJoint>
        <multiplier>-1.0</multiplier>
        <offset>0.0</offset>
        <robotNamespace>/</robotNamespace>
      </plugin>
      <static>0</static>
      <plugin name='mimic_gripper_r_finger_joint' filename='libgazebo_mimic_joint_plugin.so'>
        <joint>gripper_joint</joint>
        <mimicJoint>gripper_r_finger_joint</mimicJoint>
        <multiplier>1.0</multiplier>
        <offset>0.0</offset>
        <robotNamespace>/</robotNamespace>
      </plugin>
      <pose frame=''>0 0 0 0 -0 0</pose>
    </model>
    <model name='coke_can'>
      <link name='link'>
        <inertial>
          <pose frame=''>0 0 0.06 0 -0 0</pose>
          <mass>0.39</mass>
          <inertia>
            <ixx>0.00055575</ixx>
            <ixy>0</ixy>
            <ixz>0</ixz>
            <iyy>0.00055575</iyy>
            <iyz>0</iyz>
            <izz>0.0001755</izz>
          </inertia>
        </inertial>
        <collision name='collision'>
          <pose frame=''>0.003937 0.004724 -0.18 0 -0 0</pose>
          <geometry>
            <mesh>
              <uri>model://coke_can/meshes/coke_can.dae</uri>
            </mesh>
          </geometry>
          <surface>
            <friction>
              <ode>
                <mu>1</mu>
                <mu2>1</mu2>
              </ode>
              <torsional>
                <ode/>
              </torsional>
            </friction>
            <contact>
              <ode>
                <kp>1e+07</kp>
                <kd>1</kd>
                <min_depth>0.001</min_depth>
                <max_vel>0.1</max_vel>
              </ode>
            </contact>
            <bounce/>
          </surface>
          <max_contacts>10</max_contacts>
        </collision>
        <visual name='visual'>
          <pose frame=''>0.003937 0.004724 -0.18 0 -0 0</pose>
          <geometry>
            <mesh>
              <uri>model://coke_can/meshes/coke_can.dae</uri>
            </mesh>
          </geometry>
        </visual>
        <self_collide>0</self_collide>
        <enable_wind>0</enable_wind>
        <kinematic>0</kinematic>
      </link>
      <pose frame=''>-0.011437 -1.52324 0 0 -0 0</pose>
    </model>
    <model name='cafe_table'>
      <static>1</static>
      <link name='link'>
        <collision name='surface'>
          <pose frame=''>0 0 0.755 0 -0 0</pose>
          <geometry>
            <box>
              <size>0.913 0.913 0.04</size>
            </box>
          </geometry>
          <max_contacts>10</max_contacts>
          <surface>
            <contact>
              <ode/>
            </contact>
            <bounce/>
            <friction>
              <torsional>
                <ode/>
              </torsional>
              <ode/>
            </friction>
          </surface>
        </collision>
        <collision name='column'>
          <pose frame=''>0 0 0.37 0 -0 0</pose>
          <geometry>
            <box>
              <size>0.042 0.042 0.74</size>
            </box>
          </geometry>
          <max_contacts>10</max_contacts>
          <surface>
            <contact>
              <ode/>
            </contact>
            <bounce/>
            <friction>
              <torsional>
                <ode/>
              </torsional>
              <ode/>
            </friction>
          </surface>
        </collision>
        <collision name='base'>
          <pose frame=''>0 0 0.02 0 -0 0</pose>
          <geometry>
            <box>
              <size>0.56 0.56 0.04</size>
            </box>
          </geometry>
          <max_contacts>10</max_contacts>
          <surface>
            <contact>
              <ode/>
            </contact>
            <bounce/>
            <friction>
              <torsional>
                <ode/>
              </torsional>
              <ode/>
            </friction>
          </surface>
        </collision>
        <visual name='visual'>
          <geometry>
            <mesh>
              <uri>model://cafe_table/meshes/cafe_table.dae</uri>
            </mesh>
          </geometry>
        </visual>
        <self_collide>0</self_collide>
        <enable_wind>0</enable_wind>
        <kinematic>0</kinematic>
      </link>
      <pose frame=''>-2.23542 -1.97252 0 0 -0 0</pose>
    </model>
    <model name='table'>
      <static>1</static>
      <link name='link'>
        <collision name='surface'>
          <pose frame=''>0 0 1 0 -0 0</pose>
          <geometry>
            <box>
              <size>1.5 0.8 0.03</size>
            </box>
          </geometry>
          <surface>
            <friction>
              <ode>
                <mu>0.6</mu>
                <mu2>0.6</mu2>
              </ode>
              <torsional>
                <ode/>
              </torsional>
            </friction>
            <contact>
              <ode/>
            </contact>
            <bounce/>
          </surface>
          <max_contacts>10</max_contacts>
        </collision>
        <visual name='visual1'>
          <pose frame=''>0 0 1 0 -0 0</pose>
          <geometry>
            <box>
              <size>1.5 0.8 0.03</size>
            </box>
          </geometry>
          <material>
            <script>
              <uri>file://media/materials/scripts/gazebo.material</uri>
              <name>Gazebo/Wood</name>
            </script>
          </material>
        </visual>
        <collision name='front_left_leg'>
          <pose frame=''>0.68 0.38 0.5 0 -0 0</pose>
          <geometry>
            <cylinder>
              <radius>0.02</radius>
              <length>1</length>
            </cylinder>
          </geometry>
          <max_contacts>10</max_contacts>
          <surface>
            <contact>
              <ode/>
            </contact>
            <bounce/>
            <friction>
              <torsional>
                <ode/>
              </torsional>
              <ode/>
            </friction>
          </surface>
        </collision>
        <visual name='front_left_leg'>
          <pose frame=''>0.68 0.38 0.5 0 -0 0</pose>
          <geometry>
            <cylinder>
              <radius>0.02</radius>
              <length>1</length>
            </cylinder>
          </geometry>
          <material>
            <script>
              <uri>file://media/materials/scripts/gazebo.material</uri>
              <name>Gazebo/Grey</name>
            </script>
          </material>
        </visual>
        <collision name='front_right_leg'>
          <pose frame=''>0.68 -0.38 0.5 0 -0 0</pose>
          <geometry>
            <cylinder>
              <radius>0.02</radius>
              <length>1</length>
            </cylinder>
          </geometry>
          <max_contacts>10</max_contacts>
          <surface>
            <contact>
              <ode/>
            </contact>
            <bounce/>
            <friction>
              <torsional>
                <ode/>
              </torsional>
              <ode/>
            </friction>
          </surface>
        </collision>
        <visual name='front_right_leg'>
          <pose frame=''>0.68 -0.38 0.5 0 -0 0</pose>
          <geometry>
            <cylinder>
              <radius>0.02</radius>
              <length>1</length>
            </cylinder>
          </geometry>
          <material>
            <script>
              <uri>file://media/materials/scripts/gazebo.material</uri>
              <name>Gazebo/Grey</name>
            </script>
          </material>
        </visual>
        <collision name='back_right_leg'>
          <pose frame=''>-0.68 -0.38 0.5 0 -0 0</pose>
          <geometry>
            <cylinder>
              <radius>0.02</radius>
              <length>1</length>
            </cylinder>
          </geometry>
          <max_contacts>10</max_contacts>
          <surface>
            <contact>
              <ode/>
            </contact>
            <bounce/>
            <friction>
              <torsional>
                <ode/>
              </torsional>
              <ode/>
            </friction>
          </surface>
        </collision>
        <visual name='back_right_leg'>
          <pose frame=''>-0.68 -0.38 0.5 0 -0 0</pose>
          <geometry>
            <cylinder>
              <radius>0.02</radius>
              <length>1</length>
            </cylinder>
          </geometry>
          <material>
            <script>
              <uri>file://media/materials/scripts/gazebo.material</uri>
              <name>Gazebo/Grey</name>
            </script>
          </material>
        </visual>
        <collision name='back_left_leg'>
          <pose frame=''>-0.68 0.38 0.5 0 -0 0</pose>
          <geometry>
            <cylinder>
              <radius>0.02</radius>
              <length>1</length>
            </cylinder>
          </geometry>
          <max_contacts>10</max_contacts>
          <surface>
            <contact>
              <ode/>
            </contact>
            <bounce/>
            <friction>
              <torsional>
                <ode/>
              </torsional>
              <ode/>
            </friction>
          </surface>
        </collision>
        <visual name='back_left_leg'>
          <pose frame=''>-0.68 0.38 0.5 0 -0 0</pose>
          <geometry>
            <cylinder>
              <radius>0.02</radius>
              <length>1</length>
            </cylinder>
          </geometry>
          <material>
            <script>
              <uri>file://media/materials/scripts/gazebo.material</uri>
              <name>Gazebo/Grey</name>
            </script>
          </material>
        </visual>
        <self_collide>0</self_collide>
        <enable_wind>0</enable_wind>
        <kinematic>0</kinematic>
      </link>
      <pose frame=''>2.10684 -2.81196 0 0 -0 0</pose>
    </model>
  </world>
</sdf>
